Go 语言的异常处理语法绝对是独树一帜，Go 语言的错误处理形式就是一朵奇葩。

一方面它鼓励你使用 C 语言的形式将错误通过返回值来进行传递，另一方面它还提供了高级语言一般都有的异常抛出和捕获的形式，但是又不鼓励你使用这个形式。

后面我们统一将返回值形式的称为「错误」，将抛出捕获形式的称为「异常」。



### 错误接口

Go 语言规定凡是实现了错误接口的对象都是错误对象，这个错误接口只定义了一个方法。

```go
type error interface {
  Error() string
}
```

注意这个接口的名称，它是小写的，是内置的全局接口。

通常一个名字如果是小写字母开头，那么它在包外就是不可见的，不过 error 是内置的特殊名称，它是全局可见的。

编写一个错误对象很简单，写一个结构体，然后挂在 Error() 方法就可以了。

```go
package main
import "fmt"

type SomeError struct {
    Reason string
}

func (s SomeError) Error() string {
    return s.Reason
}

func main() {
    var err error = SomeError{"something happened"}
    fmt.Println(err)
}

---------------
something happened
```



#### errors包

对于上面代码中错误对象的形式非常常用，所以 Go 语言内置了一个通用错误类型，在 errors 包里。这个包还提供了一个 New() 函数让我们方便地创建一个通用错误。

```go
package errors

func New(text string) error {
    return &errorString{text}
}

type errorString struct {
    s string
}

func (e *errorString) Error() string {
    return e.s
}
```


注意这个结构体 errorString 是首字母小写的，意味着我们无法直接使用这个类型的名字来构造错误对象，而必须使用 New() 函数。

```
var err = errors.New("something happened")
```


如果你的错误字符串需要定制一些参数，可使用 fmt 包提供了 Errorf 函数

```
var thing = "something"
var err = fmt.Errorf("%s happened", thing)
```



### 体验错误处理

#### 读取文件

尝试一下 Go 语言的错误处理，读文件需要使用内置的 os 包。

```go
package main

import "os"
import "fmt"

func main() {
    // 打开文件
    var f, err = os.Open("main.go")
    if err != nil {
        // 文件不存在、权限等原因
        fmt.Println("open file failed reason:" + err.Error())
        return
    }
    // 推迟到函数尾部调用，确保文件会关闭
    defer f.Close()
    // 存储文件内容
    var content = []byte{}
    // 临时的缓冲，按块读取，一次最多读取 100 字节
    var buf = make([]byte, 100)
    for {
        // 读文件，将读到的内容填充到缓冲
        n, err := f.Read(buf)
        if n > 0 {
            // 将读到的内容聚合起来
            // … 操作符，它的作用是将切片参数的所有元素展开后传递给 append 函数。你可能会担心如果切片里有成百上千的元素，展开成元素再传递会不会非常耗费性能。这个不必担心，展开只是形式上的展开，在实现上其实并没有展开，传递过去的参数本质上还是切片。
            content = append(content, buf[:n]...)
        }
        if err != nil {
            // 遇到流结束或者其它错误
            break
        }
    }
    // 输出文件内容
    fmt.Println(string(content))
}

-------
package main

import "os"
import "fmt"
```



#### 体验redis

使用第三方包，需要使用 go get 指令下载这个包，该指令会将第三方包放到 GOPATH 目录下。

```
go get github.com/go-redis/redis
```


下面我要实现一个小功能，获取 Redis 中两个整数值，然后相乘，再存入 Redis 中

```go
package main

import "fmt"
import "strconv"
import "github.com/go-redis/redis"

func main() {
 // 定义客户端对象，内部包含一个连接池
    var client = redis.NewClient(&redis.Options {
        Addr: "localhost:6379",
    })

    // 定义三个重要的整数变量值，默认都是零
    var val1, val2, val3 int

    // 获取第一个值
    valstr1, err := client.Get("value1").Result()
    if err == nil {
        val1, err = strconv.Atoi(valstr1)
        if err != nil {
            fmt.Println("value1 not a valid integer")
            return
        }
    } else if err != redis.Nil {
        fmt.Println("redis access error reason:" + err.Error())
        return
    }

    // 获取第二个值
    valstr2, err := client.Get("value2").Result()
    if err == nil {
        val2, err = strconv.Atoi(valstr2)
        if err != nil {
            fmt.Println("value1 not a valid integer")
            return
        }
    } else if err != redis.Nil {
        fmt.Println("redis access error reason:" + err.Error())
        return
    }

    // 保存第三个值
    val3 = val1 * val2
    ok, err := client.Set("value3",val3, 0).Result()
    if err != nil {
        fmt.Println("set value error reason:" + err.Error())
        return
    }
    fmt.Println(ok)
}

------
OK
```


因为 Go 语言中不轻易使用异常语句，所以对于任何可能出错的地方都需要判断返回值的错误信息。上面代码中除了访问 Redis 需要判断之外，字符串转整数也需要判断。

另外还有一个需要特别注意的是因为字符串的零值是空串而不是 nil，你不好从字符串内容本身判断出 Redis 是否存在这个 key 还是对应 key 的 value 为空串，需要通过返回值的错误信息来判断。代码中的 redis.Nil 就是客户端专门为 key 不存在这种情况而定义的错误对象。



### 异常与捕捉

#### panic

 panic 和 recover 全局函数让我们可以抛出异常、捕获异常。它类似于其它高级语言里常见的 throw try catch 语句，但是又很不一样，比如 panic 函数可以抛出来任意对象。下面我们看一个使用 panic 的例子

```go
import "fmt"

var negErr = fmt.Errorf("non positive number")

func main() {
    fmt.Println(fact(10))
    fmt.Println(fact(5))
    fmt.Println(fact(-5))
    fmt.Println(fact(15))
}

// 让阶乘函数返回错误太不雅观了
// 使用 panic 会合适一些
func fact(a int) int{
    if a <= 0 {
        panic(negErr)
    }
    var r = 1
    for i :=1;i<=a;i++ {
        r *= i
    }
    return r
}

-------
3628800
120
panic: non positive number

goroutine 1 [running]:
main.fact(0xfffffffffffffffb, 0x1)
    /Users/qianwp/go/src/github.com/pyloque/practice/main.go:16 +0x75
main.main()
    /Users/qianwp/go/src/github.com/pyloque/practice/main.go:10 +0x122
exit status 2
```

下面我们使用 recover 函数来保护它，recover 函数需要结合 defer 语句一起使用，这样可以确保 recover() 逻辑在程序异常的时候也可以得到调用。



#### recover

```go
package main

import "fmt"

var negErr = fmt.Errorf("non positive number")

func main() {
    defer func() {
        if err := recover(); err != nil {
            fmt.Println("error catched"， err)
        }
    }()  //括号表示对匿名函数进行了调用
    fmt.Println(fact(10))
    fmt.Println(fact(5))
    fmt.Println(fact(-5))
    fmt.Println(fact(15))
}

func fact(a int) int{
    if a <= 0 {
        panic(negErr)
    }
    var r = 1
    for i :=1;i<=a;i++ {
        r *= i
    }
    return r
}

-------
3628800
120
error catched non positive number
```

panic 抛出的对象未必是错误对象，而 recover() 返回的对象正是 panic 抛出来的对象，所以它也不一定是错误对象。

我们经常还需要对 recover() 返回的结果进行判断，以挑选出我们愿意处理的异常对象类型，对于那些不愿意处理的，可以选择再次抛出来，让上层来处理。

```go
defer func() {
    if err := recover(); err != nil {
        if err == negErr {
            fmt.Println("error catched", err)
        } else {
            panic(err)  // rethrow
        }
    }
}()
```

