Tags:[python]

### 错误和异常

```python
try:
    ...
except exception1:
    ...
# except exception2,e python2的写法
except exception2 as e: 
    ...
except:
    ...
else:
    如果没有异常则执行
finally:
    ...
```

- try - 有异常 - except 1 或者 2，都没有，到except - finally
- try - 无异常 - else - finally
- 打印异常 print(exception1),print(e)



### sys.exc_info

看异常的值：

```python
import sys
try:
	 raise ValueError("haha")
except:
	type, value, traceback = sys.exc_info()
	print type, value, traceback
# out:
<type 'exceptions.ValueError'> haha <traceback object at 0x7f0c0a885e60>
```

  

### 抛异常

`raise StopIteration`
StopIteration是一个类。抛出异常时，会自动有一个中间环节，就是生成StopIteration的一个对象。Python实际上抛出的，是这个对象。当然，也可以自行生成对象:
`raise StopIteration()`

```python
try:
    print("haha")
    raise ValueError("don't allow to say haha")
#except Exception , e:
except Exception as e:
    print(e)

out:
haha
don't allow to say haha
```



#### args

```python
#上方例子改为：
raise ValueError("don't allow to say haha"， ‘aaa’, 'bbb')

out:
haha
("don't allow to say haha", 'aaa', 'bbb')
```

此时我们可以看下异常类的定义：

```python
class BaseException(object):
    def __init__(self, *args):
        self.args = args

    def __str__(self):
        return str(self.args[0]
                   if len(self.args) <= 1
                   else self.args)

    def __repr__(self):
        func_args = repr(self.args) if self.args else "()"
        return self.__class__.__name__ + func_args
```



#### 捕获后抛异常

有时候我们捕获异常后，希望记录下再次抛出去：

```python
logger = logging.getLogger(__name__)

try:
    do_something_in_app_that_breaks_easily()
except AppError as error:
    logger.error(error)
    raise                 # just this!
    # raise AppError      # Don't do this, you'll lose the stack trace!
```

最好不要用第二种方式，会丢失栈信息。

也不要用`raise sys.exc_info()[0], sys.exc_info()[1], sys.exc_info()[2]`, 

因为python2和3这句话是不同的， 2可以用，3不会编译通过。



### 自定义异常

上方有异常类的定义， 自定义异常类：

```python
class MyExecption(Exception):
    def __init__(self, arg):
        self.args = arg

	def __str__(self):
        return str(self.args)
    try:
        raise MyExecption("my exception")
        except MyExecption as e:
        print e
```

这样输出:

`('m', 'y', ' ', 'e', 'x', 'c', 'e', 'p', 't', 'i', 'o', 'n')`

改为` def __init__(self, *arg):`

则输出： `('my exception',)`



其实可以定义自己的字段：

```python
    class MyException(Exception):
        def __init__(self, msg):
            self.message = msg

        def __str__(self):
            return str(self.message)
    try:
        raise MyException('my exection')
    except MyException as e:
        print(e)
```

message 字段在python2默认是在Excption类中的，不过我们定义也没有什么问题，或者可以定义其他名字的地段。

